---
title: "Advanced Exception Handling Techniques in C++: Custom Exceptions, Nested Exceptions, and Resource Cleanup"
datePublished: Wed May 10 2023 21:07:40 GMT+0000 (Coordinated Universal Time)
cuid: clhi6za47000008mlf2wndese
slug: advanced-exception-handling-techniques-in-c-custom-exceptions-nested-exceptions-and-resource-cleanup
cover: https://cdn.hashnode.com/res/hashnode/image/upload/v1683752615017/ef0e71db-c6b6-49b8-ab31-4835387ef536.jpeg
ogImage: https://cdn.hashnode.com/res/hashnode/image/upload/v1683752850264/3fc58ec6-35e5-4b15-bbeb-594f594bae8a.jpeg
tags: cpp, exceptionhandling, nested-exceptions, resource-cleanup

---

Exception handling is a crucial aspect of C++ programming, allowing you to handle errors and exceptional situations gracefully. The basic concepts of exception handling include try, catch, and throw statements. However, there's more to it than just the basics. In this article, we will explore some advanced topics related to exception handling, such as custom exceptions, nested exceptions, and resource cleanup.

## Custom Exceptions

C++ allows you to create custom exception classes to provide more information about the error and improve error handling. Custom exceptions can be derived from the standard `std::exception` class or its subclasses. By creating custom exception classes, you can include additional information, such as error codes or custom error messages.

```cpp
#include <stdexcept>
#include <string>

class CustomException : public std::runtime_error {
public:
    CustomException(const std::string& message) : std::runtime_error(message) {}
};
```

To throw a custom exception, use the `throw` keyword followed by an instance of your custom exception class:

```cpp
void myFunction() {
    throw CustomException("An error occurred in myFunction");
}
```

To catch a custom exception, add a catch block for your custom exception class:

```cpp
try {
    myFunction();
} catch (const CustomException& e) {
    std::cerr << "Caught custom exception: " << e.what() << std::endl;
}
```

## Nested Exceptions

C++11 introduced support for nested exceptions, which allow you to catch an exception and then throw another exception that contains the original exception as its cause. This can be useful for providing more context about an error or for chaining exceptions in a multi-layered application.

To create a nested exception, use the `std::nested_exception` class or derive your custom exception class from `std::nested_exception`:

```cpp
#include <stdexcept>
#include <string>
#include <exception>

class NestedException : public std::runtime_error, public std::nested_exception {
public:
    NestedException(const std::string& message) : std::runtime_error(message) {}
};
```

To throw a nested exception, first catch the original exception and then throw the nested exception using the `std::throw_with_nested` function:

```cpp
void myFunction() {
    try {
        // Code that may throw an exception
    } catch (...) {
        std::throw_with_nested(NestedException("An error occurred in myFunction"));
    }
}
```

To catch a nested exception, use the `std::rethrow_if_nested` function inside the catch block:

```cpp
try {
    myFunction();
} catch (const NestedException& e) {
    std::cerr << "Caught nested exception: " << e.what() << std::endl;
    try {
        std::rethrow_if_nested(e);
    } catch (const std::exception& inner) {
        std::cerr << "  Caused by: " << inner.what() << std::endl;
    }
}
```

## Resource Cleanup

When an exception is thrown, it is important to ensure that any resources acquired during the program's execution are properly released. This can be achieved using the RAII (Resource Acquisition Is Initialization) technique or by using smart pointers.

RAII involves creating classes that acquire resources in their constructors and release resources in their destructors. When an instance of a RAII class goes out of scope, the destructor is called, releasing the resources.

```cpp
class Resource {
public:
    Resource() {
        // Acquire the resource
    }

    ~Resource() {
        // Release the resource
    }
};
```

When using RAII, resources are automatically cleaned up when an exception is thrown, even if the catch block does not explicitly handle resource cleanup:

```cpp
void myFunction() {
    Resource resource;

    // Code that may throw an exception
}
```

In the example above, if an exception is thrown during the execution of `myFunction`, the `Resource` destructor will be called automatically, releasing the resources.

Alternatively, you can use smart pointers, such as `std::unique_ptr` or `std::shared_ptr`, to manage resources. Smart pointers automatically release the resources they manage when they go out of scope, ensuring that resources are cleaned up even in the presence of exceptions.

```cpp
#include <memory>

void myFunction() {
    std::unique_ptr<Resource> resource(new Resource());

    // Code that may throw an exception
}
```

In this example, if an exception is thrown during the execution of `myFunction`, the `std::unique_ptr` destructor will be called automatically, deleting the `Resource` object and releasing its resources.

## Conclusion

Exception handling is an essential aspect of C++ programming, allowing you to handle errors and exceptional situations gracefully. In this article, we explored advanced topics related to exception handling, such as custom exceptions, nested exceptions, and resource cleanup. Understanding these advanced techniques is crucial for writing robust and maintainable C++ code.